[2024-12-19T16:35:39.071+0000] {local_task_job_runner.py:123} INFO - ::group::Pre task execution logs
[2024-12-19T16:35:39.107+0000] {taskinstance.py:2613} INFO - Dependencies all met for dep_context=non-requeueable deps ti=<TaskInstance: postgres_to_pdf_report.generate_pdf manual__2024-12-19T16:35:22.063231+00:00 [queued]>
[2024-12-19T16:35:39.127+0000] {taskinstance.py:2613} INFO - Dependencies all met for dep_context=requeueable deps ti=<TaskInstance: postgres_to_pdf_report.generate_pdf manual__2024-12-19T16:35:22.063231+00:00 [queued]>
[2024-12-19T16:35:39.128+0000] {taskinstance.py:2866} INFO - Starting attempt 1 of 2
[2024-12-19T16:35:39.409+0000] {taskinstance.py:2889} INFO - Executing <Task(PythonOperator): generate_pdf> on 2024-12-19 16:35:22.063231+00:00
[2024-12-19T16:35:39.424+0000] {warnings.py:112} WARNING - /home/***/.local/lib/python3.12/site-packages/***/task/task_runner/standard_task_runner.py:70: DeprecationWarning: This process (pid=82) is multi-threaded, use of fork() may lead to deadlocks in the child.
  pid = os.fork()

[2024-12-19T16:35:39.428+0000] {standard_task_runner.py:72} INFO - Started process 95 to run task
[2024-12-19T16:35:39.429+0000] {standard_task_runner.py:104} INFO - Running: ['***', 'tasks', 'run', 'postgres_to_pdf_report', 'generate_pdf', 'manual__2024-12-19T16:35:22.063231+00:00', '--job-id', '12', '--raw', '--subdir', 'DAGS_FOLDER/pdf_report.py', '--cfg-path', '/tmp/tmpc26puiq_']
[2024-12-19T16:35:39.432+0000] {standard_task_runner.py:105} INFO - Job 12: Subtask generate_pdf
[2024-12-19T16:35:39.544+0000] {task_command.py:467} INFO - Running <TaskInstance: postgres_to_pdf_report.generate_pdf manual__2024-12-19T16:35:22.063231+00:00 [running]> on host 889bca9a6e83
[2024-12-19T16:35:39.788+0000] {taskinstance.py:3132} INFO - Exporting env vars: AIRFLOW_CTX_DAG_OWNER='***' AIRFLOW_CTX_DAG_ID='postgres_to_pdf_report' AIRFLOW_CTX_TASK_ID='generate_pdf' AIRFLOW_CTX_EXECUTION_DATE='2024-12-19T16:35:22.063231+00:00' AIRFLOW_CTX_TRY_NUMBER='1' AIRFLOW_CTX_DAG_RUN_ID='manual__2024-12-19T16:35:22.063231+00:00'
[2024-12-19T16:35:39.793+0000] {logging_mixin.py:190} INFO - Task instance is in running state
[2024-12-19T16:35:39.796+0000] {logging_mixin.py:190} INFO -  Previous state of the Task instance: queued
[2024-12-19T16:35:39.797+0000] {logging_mixin.py:190} INFO - Current task name:generate_pdf state:running start_date:2024-12-19 16:35:39.109148+00:00
[2024-12-19T16:35:39.799+0000] {logging_mixin.py:190} INFO - Dag name:postgres_to_pdf_report and current dag run status:running
[2024-12-19T16:35:39.802+0000] {taskinstance.py:731} INFO - ::endgroup::
[2024-12-19T16:35:39.851+0000] {taskinstance.py:3311} ERROR - Task failed with exception
Traceback (most recent call last):
  File "/home/airflow/.local/lib/python3.12/site-packages/airflow/models/taskinstance.py", line 767, in _execute_task
    result = _execute_callable(context=context, **execute_callable_kwargs)
             ^^^^^^^^^^^^^^^^^^^^^^^^^^^^^^^^^^^^^^^^^^^^^^^^^^^^^^^^^^^^^
  File "/home/airflow/.local/lib/python3.12/site-packages/airflow/models/taskinstance.py", line 733, in _execute_callable
    return ExecutionCallableRunner(
           ^^^^^^^^^^^^^^^^^^^^^^^^
  File "/home/airflow/.local/lib/python3.12/site-packages/airflow/utils/operator_helpers.py", line 252, in run
    return self.func(*args, **kwargs)
           ^^^^^^^^^^^^^^^^^^^^^^^^^^
  File "/home/airflow/.local/lib/python3.12/site-packages/airflow/models/baseoperator.py", line 422, in wrapper
    return func(self, *args, **kwargs)
           ^^^^^^^^^^^^^^^^^^^^^^^^^^^
  File "/home/airflow/.local/lib/python3.12/site-packages/airflow/operators/python.py", line 238, in execute
    return_value = self.execute_callable()
                   ^^^^^^^^^^^^^^^^^^^^^^^
  File "/home/airflow/.local/lib/python3.12/site-packages/airflow/operators/python.py", line 256, in execute_callable
    return runner.run(*self.op_args, **self.op_kwargs)
           ^^^^^^^^^^^^^^^^^^^^^^^^^^^^^^^^^^^^^^^^^^^
  File "/home/airflow/.local/lib/python3.12/site-packages/airflow/utils/operator_helpers.py", line 252, in run
    return self.func(*args, **kwargs)
           ^^^^^^^^^^^^^^^^^^^^^^^^^^
  File "/opt/airflow/dags/pdf_report.py", line 55, in create_pdf_report
    pdf.output(pdf_file_path)
  File "/home/airflow/.local/lib/python3.12/site-packages/fpdf/fpdf.py", line 1079, in output
    f=open(name,'wb')
      ^^^^^^^^^^^^^^^
FileNotFoundError: [Errno 2] No such file or directory: '/mnt/d/reports/report_20241219163539.pdf'
[2024-12-19T16:35:39.906+0000] {logging_mixin.py:190} INFO - Task instance in failure state
[2024-12-19T16:35:39.909+0000] {logging_mixin.py:190} INFO - Task start:2024-12-19 16:35:39.109148+00:00 end:2024-12-19 16:35:39.904558+00:00 duration:0.79541
[2024-12-19T16:35:39.910+0000] {logging_mixin.py:190} INFO - Task:<Task(PythonOperator): generate_pdf> dag:<DAG: postgres_to_pdf_report> dagrun:<DagRun postgres_to_pdf_report @ 2024-12-19 16:35:22.063231+00:00: manual__2024-12-19T16:35:22.063231+00:00, state:running, queued_at: 2024-12-19 16:35:22.088348+00:00. externally triggered: True>
[2024-12-19T16:35:39.912+0000] {logging_mixin.py:190} INFO - Failure caused by [Errno 2] No such file or directory: '/mnt/d/reports/report_20241219163539.pdf'
[2024-12-19T16:35:39.913+0000] {taskinstance.py:1225} INFO - Marking task as UP_FOR_RETRY. dag_id=postgres_to_pdf_report, task_id=generate_pdf, run_id=manual__2024-12-19T16:35:22.063231+00:00, execution_date=20241219T163522, start_date=20241219T163539, end_date=20241219T163539
[2024-12-19T16:35:40.004+0000] {taskinstance.py:340} INFO - ::group::Post task execution logs
[2024-12-19T16:35:40.006+0000] {standard_task_runner.py:124} ERROR - Failed to execute job 12 for task generate_pdf ([Errno 2] No such file or directory: '/mnt/d/reports/report_20241219163539.pdf'; 95)
Traceback (most recent call last):
  File "/home/airflow/.local/lib/python3.12/site-packages/airflow/task/task_runner/standard_task_runner.py", line 117, in _start_by_fork
    ret = args.func(args, dag=self.dag)
          ^^^^^^^^^^^^^^^^^^^^^^^^^^^^^
  File "/home/airflow/.local/lib/python3.12/site-packages/airflow/cli/cli_config.py", line 49, in command
    return func(*args, **kwargs)
           ^^^^^^^^^^^^^^^^^^^^^
  File "/home/airflow/.local/lib/python3.12/site-packages/airflow/utils/cli.py", line 116, in wrapper
    return f(*args, **kwargs)
           ^^^^^^^^^^^^^^^^^^
  File "/home/airflow/.local/lib/python3.12/site-packages/airflow/cli/commands/task_command.py", line 483, in task_run
    task_return_code = _run_task_by_selected_method(args, _dag, ti)
                       ^^^^^^^^^^^^^^^^^^^^^^^^^^^^^^^^^^^^^^^^^^^^
  File "/home/airflow/.local/lib/python3.12/site-packages/airflow/cli/commands/task_command.py", line 256, in _run_task_by_selected_method
    return _run_raw_task(args, ti)
           ^^^^^^^^^^^^^^^^^^^^^^^
  File "/home/airflow/.local/lib/python3.12/site-packages/airflow/cli/commands/task_command.py", line 341, in _run_raw_task
    return ti._run_raw_task(
           ^^^^^^^^^^^^^^^^^
  File "/home/airflow/.local/lib/python3.12/site-packages/airflow/utils/session.py", line 97, in wrapper
    return func(*args, session=session, **kwargs)
           ^^^^^^^^^^^^^^^^^^^^^^^^^^^^^^^^^^^^^^
  File "/home/airflow/.local/lib/python3.12/site-packages/airflow/models/taskinstance.py", line 3005, in _run_raw_task
    return _run_raw_task(
           ^^^^^^^^^^^^^^
  File "/home/airflow/.local/lib/python3.12/site-packages/airflow/models/taskinstance.py", line 273, in _run_raw_task
    TaskInstance._execute_task_with_callbacks(
  File "/home/airflow/.local/lib/python3.12/site-packages/airflow/models/taskinstance.py", line 3159, in _execute_task_with_callbacks
    result = self._execute_task(context, task_orig)
             ^^^^^^^^^^^^^^^^^^^^^^^^^^^^^^^^^^^^^^
  File "/home/airflow/.local/lib/python3.12/site-packages/airflow/models/taskinstance.py", line 3183, in _execute_task
    return _execute_task(self, context, task_orig)
           ^^^^^^^^^^^^^^^^^^^^^^^^^^^^^^^^^^^^^^^
  File "/home/airflow/.local/lib/python3.12/site-packages/airflow/models/taskinstance.py", line 767, in _execute_task
    result = _execute_callable(context=context, **execute_callable_kwargs)
             ^^^^^^^^^^^^^^^^^^^^^^^^^^^^^^^^^^^^^^^^^^^^^^^^^^^^^^^^^^^^^
  File "/home/airflow/.local/lib/python3.12/site-packages/airflow/models/taskinstance.py", line 733, in _execute_callable
    return ExecutionCallableRunner(
           ^^^^^^^^^^^^^^^^^^^^^^^^
  File "/home/airflow/.local/lib/python3.12/site-packages/airflow/utils/operator_helpers.py", line 252, in run
    return self.func(*args, **kwargs)
           ^^^^^^^^^^^^^^^^^^^^^^^^^^
  File "/home/airflow/.local/lib/python3.12/site-packages/airflow/models/baseoperator.py", line 422, in wrapper
    return func(self, *args, **kwargs)
           ^^^^^^^^^^^^^^^^^^^^^^^^^^^
  File "/home/airflow/.local/lib/python3.12/site-packages/airflow/operators/python.py", line 238, in execute
    return_value = self.execute_callable()
                   ^^^^^^^^^^^^^^^^^^^^^^^
  File "/home/airflow/.local/lib/python3.12/site-packages/airflow/operators/python.py", line 256, in execute_callable
    return runner.run(*self.op_args, **self.op_kwargs)
           ^^^^^^^^^^^^^^^^^^^^^^^^^^^^^^^^^^^^^^^^^^^
  File "/home/airflow/.local/lib/python3.12/site-packages/airflow/utils/operator_helpers.py", line 252, in run
    return self.func(*args, **kwargs)
           ^^^^^^^^^^^^^^^^^^^^^^^^^^
  File "/opt/airflow/dags/pdf_report.py", line 55, in create_pdf_report
    pdf.output(pdf_file_path)
  File "/home/airflow/.local/lib/python3.12/site-packages/fpdf/fpdf.py", line 1079, in output
    f=open(name,'wb')
      ^^^^^^^^^^^^^^^
FileNotFoundError: [Errno 2] No such file or directory: '/mnt/d/reports/report_20241219163539.pdf'
[2024-12-19T16:35:40.050+0000] {local_task_job_runner.py:266} INFO - Task exited with return code 1
[2024-12-19T16:35:40.107+0000] {taskinstance.py:3895} INFO - 0 downstream tasks scheduled from follow-on schedule check
[2024-12-19T16:35:40.111+0000] {local_task_job_runner.py:245} INFO - ::endgroup::
